<?xml version="1.0"?>

<robot xmlns:sensor="http://playerstage.sourceforge.net/gazebo/xmlschema/#sensor"
       xmlns:controller="http://playerstage.sourceforge.net/gazebo/xmlschema/#controller"
       xmlns:interface="http://playerstage.sourceforge.net/gazebo/xmlschema/#interface"
       xmlns:xacro="http://ros.org/wiki/xacro"
name="skj">

  <!-- Chassis -->
	<link name="base_link">
		<inertial>
			<mass value="63.2"/>
			<origin xyz="0 0 0.177"/>
			<inertia ixx="0.3338" ixy="0.0" ixz="0.0"
				 iyy="0.4783" iyz="0.0"
				 izz="0.3338"/>
		</inertial>
		<visual name="skj_base_visual">
			<origin xyz="0 0 0.177" rpy="0 0 0"/>
			<geometry name="skj_geom">
				<!-- mesh filename="package://amr_robots_description/meshes/seekurjr_meshes/body.stl"/ -->
        <box size="0.440 1.050 0.500" />
			</geometry>
			<material name="BodyBlue">
				<color rgba="0.0 0.0 1.0 1.0"/>
			</material>
		</visual>
		<collision>
			<origin xyz="0 0 0.177" rpy="0 0 0"/>
				<geometry>
					<!-- mesh filename="package://amr_robots_description/meshes/seekurjr_meshes/body_collision.stl"/ -->
          <box size="0.440 1.050 0.500" />
				</geometry>
		</collision>
	</link>

	<gazebo reference="base_link">
		<material value="Gazebo/Blue"/>
	</gazebo>

  <xacro:macro name="skj_wheel" params="end side endreflect sidereflect">

    <link name="skj_${end}_${side}_wheel">
      <inertial>
        <mass value="4.2"/>	
        <origin xyz="0 0 0"/>
        <inertia ixx="0.012411765597" ixy="0" ixz="0"
           iyy="0.015218160428" iyz="0" izz="0.011763977943"/>
      </inertial>
      <visual name="base_visual">
        <origin xyz="0 0 0" rpy="-1.570795 0 0"/>
        <geometry name="skj_wheel_geom">
          <!-- mesh filename="package://amr_robots_description/meshes/skj_meshes/wheel.stl"/ -->
          <cylinder radius="0.2" length="0.2"/>
        </geometry>
        <material name="WheelBlack">
          <color rgba="0.117 0.117 0.117 1"/>
        </material>
      </visual>
      <collision>
        <origin xyz="0 0 0" rpy="${-3.1415927/2} 0 0"/>
        <geometry>
          <cylinder radius="0.2" length="0.2"/>
        </geometry>
      </collision>
    </link>

    <gazebo reference="skj_${end}_${side}_wheel">
      <material value="Gazebo/Black"/>
    </gazebo>

    <joint name="skj_${end}_${side}_wheel_joint" type="continuous">
      <axis xyz="0 1 0"/>
      <anchor xyz="0 0 0"/>
      <limit effort="100" velocity="100" />
      <joint_properties damping="0.7"/>
      <origin xyz="${endreflect*-0.134} ${sidereflect*0.156} 0.111" rpy="0 0 0"/>
      <parent link="base_link"/>
      <child link="skj_${end}_${side}_wheel"/>
    </joint>

    <gazebo reference="skj_${end}_${side}_wheel">
      <kp>1000000.0</kp> <!-- kp and kd for rubber -->
      <kd>100.0</kd>
      <mu1>1.0</mu1> <!-- was 10.0 -->
      <mu2>1.0</mu2>
      <!-- todo how to get these ODE params in: slip1, slip2 -->
      <fdir1>0 1 0</fdir1> <!-- is this correct? -->
      <maxVel>1.0</maxVel>
      <minDepth>0.00</minDepth>
      <material value="Gazebo/Black" />
    </gazebo>
    
  </xacro:macro>


  <xacro:skj_wheel end="front" side="left" endreflect="1" sidereflect="1" />
  <xacro:skj_wheel end="front" side="right" endreflect="1" sidereflect="-1" />
  <xacro:skj_wheel end="back" side="left" endreflect="-1" sidereflect="1" />
  <xacro:skj_wheel end="back" side="right" endreflect="-1" sidereflect="-1" />

  <gazebo>
    <plugin name="skid_steer_drive_controller" filename="libgazebo_ros_skid_steer_drive.so">
      <updateRate>100.0</updateRate>
      <robotNamespace>/</robotNamespace>
      <leftFrontJoint>skj_front_left_wheel_joint</leftFrontJoint>
      <rightFrontJoint>skj_front_right_wheel_joint</rightFrontJoint>
      <leftRearJoint>skj_back_left_wheel_joint</leftRearJoint>
      <rightRearJoint>skj_back_right_wheel_joint</rightRearJoint>
      <wheelSeparation>0.68</wheelSeparation>
      <wheelDiameter>0.40</wheelDiameter>
      <robotBaseFrame>base_link</robotBaseFrame>
      <torque>400</torque>
      <MaxForce>5.0</MaxForce>
      <commandTopic>cmd_vel</commandTopic>
      <odometryTopic>odom</odometryTopic>
      <odometryFrame>odom</odometryFrame>
      <broadcastTF>1</broadcastTF>
    </plugin>
  </gazebo>

</robot>

