<?xml version="1.0" ?>
<!-- =================================================================================== -->
<!-- |    This document was autogenerated by xacro from terabot-arm.urdf.xacro         | -->
<!-- |    EDITING THIS FILE BY HAND IS NOT RECOMMENDED                                 | -->
<!-- =================================================================================== -->
<robot name="terabot-arm" xmlns:xacro="http://www.ros.org/wiki/xacro">
  <material name="Blue">
    <color rgba="0.0 0.0 1.0 1.0"/>
  </material>
  <material name="Grey">
    <color rgba="0.25 0.25 0.25 1.0"/>
  </material>
  <material name="Black">
    <color rgba="1 1 1 1.0"/>
  </material>
  <material name="orange">
    <color rgba="1.0 0.423529411765 0.0392156862745 1.0"/>
  </material>
  <material name="brown">
    <color rgba="0.870588235294 0.811764705882 0.764705882353 1.0"/>
  </material>
  <material name="red">
    <color rgba="0.8 0.0 0.0 1.0"/>
  </material>
  <material name="white">
    <color rgba="1.0 1.0 1.0 1.0"/>
  </material>
  <link name="arm_base_link">
    <visual>
      <origin rpy="0 -1.57079632679 1.57079632679" xyz="0 0 0.04"/>
      <geometry>
        <mesh filename="package://terabot_description/meshes/base.stl" scale="0.001 0.001 0.001"/>
      </geometry>
      <material name="orange"/>
    </visual>
    <collision>
      <geometry>
        <cylinder length="0.1145" radius="0.04"/>
      </geometry>
      <origin xyz="0 0 0.05725"/>
    </collision>
    <inertial>
      <origin rpy="0 0 0" xyz="0 0 0"/>
      <mass value="1"/>
      <inertia ixx="1.0" ixy="0.0" ixz="0.0" iyy="1.0" iyz="0.0" izz="1.0"/>
    </inertial>
  </link>
  <joint name="shoulder_joint" type="revolute">
    <origin rpy="0 0 -3.14159265359" xyz="0 0 0.08"/>
    <axis xyz="0 0 1"/>
    <limit effort="1000.0" lower="-2.96705972839" upper="2.96705972839" velocity="0.5"/>
    <parent link="arm_base_link"/>
    <child link="shoulder_link"/>
    <dynamics damping="0.001"/>
  </joint>
  <link name="shoulder_link">
    <visual>
      <origin rpy="0 -1.57079632679 -1.57079632679" xyz="0 0 -0.04"/>
      <geometry>
        <mesh filename="package://terabot_description/meshes/shoulder.stl" scale="0.001 0.001 0.001"/>
      </geometry>
      <material name="orange"/>
    </visual>
    <collision>
      <origin rpy="0 -1.57079632679 1.57079632679" xyz="0 0 -0.04"/>
      <geometry>
        <mesh filename="package://terabot_description/meshes/shoulder.stl" scale="0.001 0.001 0.001"/>
      </geometry>
      <material name="orange"/>
    </collision>
    <inertial>
      <origin rpy="0 0 0" xyz="0 0 0"/>
      <mass value="1"/>
      <inertia ixx="1.0" ixy="0.0" ixz="0.0" iyy="1.0" iyz="0.0" izz="1.0"/>
    </inertial>
  </link>
  <joint name="lower_arm_joint" type="revolute">
    <origin rpy="1.57079632679 -1.57079632679 -3.14159265359" xyz="0 0 0.1145"/>
    <axis xyz="0 0 1"/>
    <limit effort="1000.0" lower="-1.57079632679" upper="0.0" velocity="0.5"/>
    <parent link="shoulder_link"/>
    <child link="lower_arm_link"/>
    <dynamics damping="0.001"/>
  </joint>
  <link name="lower_arm_link">
    <visual>
      <origin rpy="0 0 0.785398163397" xyz="-0.102 -0.1045 0"/>
      <geometry>
        <mesh filename="package://terabot_description/meshes/lower_arm.stl" scale="0.001 0.001 0.001"/>
      </geometry>
      <material name="orange"/>
    </visual>
    <collision>
      <origin rpy="0 0 0.785398163397" xyz="-0.102 -0.1045 0"/>
      <geometry>
        <mesh filename="package://terabot_description/meshes/lower_arm.stl" scale="0.001 0.001 0.001"/>
      </geometry>
      <material name="orange"/>
    </collision>
    <inertial>
      <origin rpy="0 0 0" xyz="0 0 0"/>
      <mass value="10"/>
      <inertia ixx="0.01" ixy="0.0" ixz="0.0" iyy="0.01" iyz="0.0" izz="0.01"/>
    </inertial>
  </link>
  <joint name="upper_arm_joint" type="revolute">
    <origin rpy="0 0 0" xyz="0.4191 0 0"/>
    <axis xyz="0 0 1"/>
    <limit effort="1000.0" lower="-2.96705972839" upper="2.82743338823" velocity="0.5"/>
    <parent link="lower_arm_link"/>
    <child link="upper_arm_link"/>
    <dynamics damping="0.007"/>
  </joint>
  <link name="upper_arm_link">
    <visual>
      <origin rpy="0 0 0" xyz="0.1021 -0.5236 0"/>
      <geometry>
        <mesh filename="package://terabot_description/meshes/upper_arm.stl" scale="0.001 0.001 0.001"/>
      </geometry>
      <material name="orange"/>
    </visual>
    <!--    <collision>
      <geometry>
        <cylinder length="${364.49*BASE}" radius="0.05"/>
      </geometry>
    </collision>-->
    <inertial>
      <origin rpy="0 0 0" xyz="0 0 0"/>
      <mass value="10"/>
      <inertia ixx="0.01" ixy="0.0" ixz="0.0" iyy="0.01" iyz="0.0" izz="0.01"/>
    </inertial>
  </link>
  <joint name="wrist_pitch_joint" type="revolute">
    <origin xyz="0.36449 0 0"/>
    <axis xyz="0 0 1"/>
    <limit effort="1000.0" lower="-2.96705972839" upper="2.96705972839" velocity="0.5"/>
    <parent link="upper_arm_link"/>
    <child link="wrist_pitch_link"/>
    <dynamics damping="0.7"/>
  </joint>
  <link name="wrist_pitch_link">
    <visual>
      <origin rpy="0 0 0" xyz="0.188245 -0.5536 0"/>
      <geometry>
        <mesh filename="package://terabot_description/meshes/wrist_pitch.stl" scale="0.001 0.001 0.001"/>
      </geometry>
      <material name="orange"/>
    </visual>
    <visual>
      <origin rpy="0 1.57079632679 0" xyz="-0.044245 0.0956 0"/>
      <geometry>
        <mesh filename="package://terabot_description/meshes/arm_camera.stl" scale="0.001 0.001 0.001"/>
      </geometry>
      <material name="orange"/>
    </visual>
    <!--    <collision>
      <geometry>
        <cylinder length="${364.49*BASE}" radius="0.05"/>
      </geometry>
    </collision>-->
    <inertial>
      <origin rpy="0 0 0" xyz="0 0 0"/>
      <mass value="0.1"/>
      <inertia ixx="1.0" ixy="0.0" ixz="0.0" iyy="1.0" iyz="0.0" izz="1.0"/>
    </inertial>
  </link>
  <!-- added end effector for calibration -->
  <joint name="end_effector_joint" type="fixed">
    <origin rpy="0 0 0" xyz="0.09 0.04 0"/>
    <!-- before modifications -->
    <!--   <origin xyz="0.09 0.04 0.006" rpy="0 0 0"/> -->
    <!-- original is 0.085 but we have the torque sensor...-->
    <axis xyz="0 0 1"/>
    <parent link="wrist_pitch_link"/>
    <child link="end_effector"/>
    <dynamics damping="100.0" friction="100.0"/>
  </joint>
  <!-- end_effector -->
  <link name="end_effector">
    <origin rpy="0 0 0" xyz="0 0 0"/>
    <inertial>
      <origin rpy="0 0 0" xyz="0 0 1"/>
      <mass value="0.01"/>
      <inertia ixx="1.0" ixy="0.0" ixz="0.0" iyy="1.0" iyz="0.0" izz="1.0"/>
    </inertial>
  </link>
  <!-- modified the following part to add end_effector link (marker) for calibration -->
  <joint name="wrist_roll_joint" type="revolute">
    <!-- origin xyz="${50*BASE+0.013+wrist_roll_joint_x_offset} ${wrist_roll_joint_z_offset} 0" rpy="0 ${PI/2} 0"/ -->
    <!-- when the parent is wrist pitch joint -->
    <origin rpy="0 1.57079632679 0" xyz="0.07 0 0"/>
    <!-- when the end effector is the parent -->
    <!--   <origin xyz="0.07 -0.005 0" rpy="0 ${PI/2} 0"/>-->
    <axis xyz="0 0 1"/>
    <limit effort="1000.0" lower="-2.96705972839" upper="2.96705972839" velocity="0.5"/>
    <parent link="end_effector"/>
    <child link="wrist_roll_link"/>
    <dynamics damping="0.7"/>
  </joint>
  <link name="wrist_roll_link">
    <visual>
      <!--      <origin xyz="-0.0322 ${0.4*BASE+wrist_roll_link_y_offset} ${-18.5*BASE+wrist_roll_link_x_offset}" rpy="0 -${PI} ${3*PI/2}" />-->
      <!-- when the parent is wrist pitch joint -->
      <origin rpy="0 -3.14159265359 4.71238898038" xyz="-0.0322 -0.0019 -0.0145"/>
      <!-- when the end effector is the parent -->
      <!--     <origin xyz="-0.0315 0 ${-18.5*BASE+wrist_roll_link_x_offset}" rpy="0 -${PI} ${3*PI/2}" />    -->
      <geometry>
        <mesh filename="package://terabot_description/meshes/wrist_roll.stl" scale="0.001 0.001 0.001"/>
      </geometry>
      <material name="orange"/>
    </visual>
    <inertial>
      <origin rpy="0 0 0" xyz="0 0 0"/>
      <mass value="0.1"/>
      <inertia ixx="1.0" ixy="0.0" ixz="0.0" iyy="1.0" iyz="0.0" izz="1.0"/>
    </inertial>
  </link>
  <joint name="gripper_l_finger_joint" type="revolute">
    <origin rpy="0 4.71238898038 4.71238898038" xyz="-0.0321 0 -0.0145"/>
    <limit effort="1000.0" lower="0.0" upper="0.698131700798" velocity="0.5"/>
    <axis xyz="0 0 -1"/>
    <parent link="wrist_roll_link"/>
    <child link="gripper_l_finger_link"/>
  </joint>
  <link name="gripper_l_finger_link">
    <visual>
      <origin rpy="-4.01054381309 -1.57079632679 4.71238898038" xyz="0 0 0"/>
      <geometry>
        <mesh filename="package://terabot_description/meshes/left_finger.stl" scale="0.001 0.001 0.001"/>
      </geometry>
      <material name="brown"/>
    </visual>
    <inertial>
      <origin rpy="0 0 0" xyz="0 0 0"/>
      <mass value="0.1"/>
      <inertia ixx="1.0" ixy="0.0" ixz="0.0" iyy="1.0" iyz="0.0" izz="1.0"/>
    </inertial>
  </link>
  <joint name="gripper_r_finger_joint" type="revolute">
    <origin rpy="0 4.71238898038 4.71238898038" xyz="0.0229 0 -0.0145"/>
    <limit effort="1000.0" lower="0.0" upper="0.698131700798" velocity="0.5"/>
    <axis xyz="0 0 1"/>
    <mimic joint="gripper_l_finger_joint"/>
    <parent link="wrist_roll_link"/>
    <child link="gripper_r_finger_link"/>
  </joint>
  <link name="gripper_r_finger_link">
    <visual>
      <origin rpy="-5.41653905791 -1.57079632679 4.71238898038" xyz="-0.0355 -0.0415 0"/>
      <geometry>
        <mesh filename="package://terabot_description/meshes/right_finger.stl" scale="0.001 0.001 0.001"/>
      </geometry>
      <material name="brown"/>
    </visual>
    <inertial>
      <origin rpy="0 0 0" xyz="0 0 0"/>
      <mass value="0.1"/>
      <inertia ixx="1.0" ixy="0.0" ixz="0.0" iyy="1.0" iyz="0.0" izz="1.0"/>
    </inertial>
  </link>
  <transmission name="tran1">
    <type>transmission_interface/SimpleTransmission</type>
    <joint name="shoulder_joint">
      <hardwareInterface>PositionJointInterface</hardwareInterface>
    </joint>
    <actuator name="motor1">
      <hardwareInterface>PositionJointInterface</hardwareInterface>
      <mechanicalReduction>1</mechanicalReduction>
    </actuator>
  </transmission>
  <transmission name="tran2">
    <type>transmission_interface/SimpleTransmission</type>
    <joint name="lower_arm_joint">
      <hardwareInterface>PositionJointInterface</hardwareInterface>
    </joint>
    <actuator name="motor2">
      <hardwareInterface>PositionJointInterface</hardwareInterface>
      <mechanicalReduction>1</mechanicalReduction>
    </actuator>
  </transmission>
  <transmission name="tran3">
    <type>transmission_interface/SimpleTransmission</type>
    <joint name="upper_arm_joint">
      <hardwareInterface>PositionJointInterface</hardwareInterface>
    </joint>
    <actuator name="motor3">
      <hardwareInterface>PositionJointInterface</hardwareInterface>
      <mechanicalReduction>1</mechanicalReduction>
    </actuator>
  </transmission>
  <transmission name="tran4">
    <type>transmission_interface/SimpleTransmission</type>
    <joint name="wrist_pitch_joint">
      <hardwareInterface>PositionJointInterface</hardwareInterface>
    </joint>
    <actuator name="motor4">
      <hardwareInterface>PositionJointInterface</hardwareInterface>
      <mechanicalReduction>1</mechanicalReduction>
    </actuator>
  </transmission>
  <transmission name="tran5">
    <type>transmission_interface/SimpleTransmission</type>
    <joint name="wrist_roll_joint">
      <hardwareInterface>PositionJointInterface</hardwareInterface>
    </joint>
    <actuator name="motor5">
      <hardwareInterface>PositionJointInterface</hardwareInterface>
      <mechanicalReduction>1</mechanicalReduction>
    </actuator>
  </transmission>
  <transmission name="tran6">
    <type>transmission_interface/SimpleTransmission</type>
    <joint name="gripper_r_finger_joint">
      <hardwareInterface>PositionJointInterface</hardwareInterface>
    </joint>
    <actuator name="motor6">
      <hardwareInterface>PositionJointInterface</hardwareInterface>
      <mechanicalReduction>1</mechanicalReduction>
    </actuator>
  </transmission>
  <transmission name="tran7">
    <type>transmission_interface/SimpleTransmission</type>
    <joint name="gripper_l_finger_joint">
      <hardwareInterface>PositionJointInterface</hardwareInterface>
    </joint>
    <actuator name="motor7">
      <hardwareInterface>PositionJointInterface</hardwareInterface>
      <mechanicalReduction>1</mechanicalReduction>
    </actuator>
  </transmission>
  <!-- ros_control plugin -->
  <gazebo>
    <plugin filename="libgazebo_ros_control.so" name="gazebo_ros_control">
      <robotNamespace>/seekur_jr</robotNamespace>
    </plugin>
  </gazebo>
  <!-- shoulder_link -->
  <gazebo reference="shoulder_link">
    <selfCollide>true</selfCollide>
    <gravity>true</gravity>
    <mu1>10.0</mu1>
    <mu2>10.0</mu2>
    <material>Gazebo/Orange</material>
  </gazebo>
  <!-- lower_arm_link -->
  <gazebo reference="lower_arm_link">
    <selfCollide>true</selfCollide>
    <gravity>true</gravity>
    <mu1>10.0</mu1>
    <mu2>10.0</mu2>
    <material>Gazebo/Black</material>
  </gazebo>
  <!-- upper_arm_link -->
  <gazebo reference="upper_arm_link">
    <selfCollide>true</selfCollide>
    <gravity>true</gravity>
    <mu1>10.0</mu1>
    <mu2>10.0</mu2>
    <material>Gazebo/Black</material>
  </gazebo>
  <!-- wrist_pitch_link -->
  <gazebo reference="wrist_pitch_link">
    <selfCollide>true</selfCollide>
    <gravity>true</gravity>
    <mu1>0.1</mu1>
    <mu2>0.1</mu2>
    <material>Gazebo/Black</material>
  </gazebo>
  <!-- wrist_roll_link -->
  <gazebo reference="wrist_roll_link">
    <selfCollide>true</selfCollide>
    <gravity>true</gravity>
    <mu1>0.1</mu1>
    <mu2>0.1</mu2>
    <material>Gazebo/Black</material>
  </gazebo>
</robot>

